2025-09-06 12:41:16,942 -  nornir.core -     INFO -        run() - Running task 'show_version' with args {} on 1 hosts
2025-09-06 12:41:18,144 - nornir.core.task -    ERROR -      start() - Host 'nxos1': task 'send_command' failed with traceback:
Traceback (most recent call last):
  File "/usr/local/python/3.12.1/lib/python3.12/site-packages/nornir/core/task.py", line 98, in start
    r = self.task(self, **self.params)
        ^^^^^^^^^^^^^^^^^^^^^^^^^^^^^^
  File "/usr/local/python/3.12.1/lib/python3.12/site-packages/nornir_scrapli/tasks/core/send_command.py", line 37, in send_command
    scrapli_conn = task.host.get_connection("scrapli", task.nornir.config)
                   ^^^^^^^^^^^^^^^^^^^^^^^^^^^^^^^^^^^^^^^^^^^^^^^^^^^^^^^
  File "/usr/local/python/3.12.1/lib/python3.12/site-packages/nornir/core/inventory.py", line 476, in get_connection
    self.open_connection(
  File "/usr/local/python/3.12.1/lib/python3.12/site-packages/nornir/core/inventory.py", line 528, in open_connection
    conn_obj.open(
  File "/usr/local/python/3.12.1/lib/python3.12/site-packages/nornir_scrapli/connection.py", line 106, in open
    connection.open()
  File "/usr/local/python/3.12.1/lib/python3.12/site-packages/scrapli/driver/base/sync_driver.py", line 106, in open
    self.channel.channel_authenticate_ssh(
  File "/usr/local/python/3.12.1/lib/python3.12/site-packages/scrapli/decorators.py", line 224, in decorate
    return _multiprocessing_timeout(
           ^^^^^^^^^^^^^^^^^^^^^^^^^
  File "/usr/local/python/3.12.1/lib/python3.12/site-packages/scrapli/decorators.py", line 115, in _multiprocessing_timeout
    return future.result()
           ^^^^^^^^^^^^^^^
  File "/usr/local/python/3.12.1/lib/python3.12/concurrent/futures/_base.py", line 449, in result
    return self.__get_result()
           ^^^^^^^^^^^^^^^^^^^
  File "/usr/local/python/3.12.1/lib/python3.12/concurrent/futures/_base.py", line 401, in __get_result
    raise self._exception
  File "/usr/local/python/3.12.1/lib/python3.12/concurrent/futures/thread.py", line 58, in run
    result = self.fn(*self.args, **self.kwargs)
             ^^^^^^^^^^^^^^^^^^^^^^^^^^^^^^^^^^
  File "/usr/local/python/3.12.1/lib/python3.12/site-packages/scrapli/channel/sync_channel.py", line 297, in channel_authenticate_ssh
    self._ssh_message_handler(output=authenticate_buf)
  File "/usr/local/python/3.12.1/lib/python3.12/site-packages/scrapli/channel/base_channel.py", line 481, in _ssh_message_handler
    raise ScrapliAuthenticationFailed(msg)
scrapli.exceptions.ScrapliAuthenticationFailed: Host key verification failed

2025-09-06 12:41:18,144 - nornir.core.task -    ERROR -      start() - Host 'nxos1': task 'show_version' failed with traceback:
Traceback (most recent call last):
  File "/usr/local/python/3.12.1/lib/python3.12/site-packages/nornir/core/task.py", line 98, in start
    r = self.task(self, **self.params)
        ^^^^^^^^^^^^^^^^^^^^^^^^^^^^^^
  File "/workspaces/Nornir/nornir_nxos/nornir_nxos.py", line 11, in show_version
    result = task.run(
             ^^^^^^^^^
  File "/usr/local/python/3.12.1/lib/python3.12/site-packages/nornir/core/task.py", line 173, in run
    raise NornirSubTaskError(task=run_task, result=r)
nornir.core.exceptions.NornirSubTaskError: Subtask: send_command (failed)


2025-09-06 12:42:19,371 -  nornir.core -     INFO -        run() - Running task 'show_version' with args {} on 1 hosts
2025-09-06 12:42:20,244 - nornir.core.task -    ERROR -      start() - Host 'nxos1': task 'send_command' failed with traceback:
Traceback (most recent call last):
  File "/usr/local/python/3.12.1/lib/python3.12/site-packages/nornir/core/task.py", line 98, in start
    r = self.task(self, **self.params)
        ^^^^^^^^^^^^^^^^^^^^^^^^^^^^^^
  File "/usr/local/python/3.12.1/lib/python3.12/site-packages/nornir_scrapli/tasks/core/send_command.py", line 37, in send_command
    scrapli_conn = task.host.get_connection("scrapli", task.nornir.config)
                   ^^^^^^^^^^^^^^^^^^^^^^^^^^^^^^^^^^^^^^^^^^^^^^^^^^^^^^^
  File "/usr/local/python/3.12.1/lib/python3.12/site-packages/nornir/core/inventory.py", line 476, in get_connection
    self.open_connection(
  File "/usr/local/python/3.12.1/lib/python3.12/site-packages/nornir/core/inventory.py", line 528, in open_connection
    conn_obj.open(
  File "/usr/local/python/3.12.1/lib/python3.12/site-packages/nornir_scrapli/connection.py", line 106, in open
    connection.open()
  File "/usr/local/python/3.12.1/lib/python3.12/site-packages/scrapli/driver/base/sync_driver.py", line 106, in open
    self.channel.channel_authenticate_ssh(
  File "/usr/local/python/3.12.1/lib/python3.12/site-packages/scrapli/decorators.py", line 224, in decorate
    return _multiprocessing_timeout(
           ^^^^^^^^^^^^^^^^^^^^^^^^^
  File "/usr/local/python/3.12.1/lib/python3.12/site-packages/scrapli/decorators.py", line 115, in _multiprocessing_timeout
    return future.result()
           ^^^^^^^^^^^^^^^
  File "/usr/local/python/3.12.1/lib/python3.12/concurrent/futures/_base.py", line 449, in result
    return self.__get_result()
           ^^^^^^^^^^^^^^^^^^^
  File "/usr/local/python/3.12.1/lib/python3.12/concurrent/futures/_base.py", line 401, in __get_result
    raise self._exception
  File "/usr/local/python/3.12.1/lib/python3.12/concurrent/futures/thread.py", line 58, in run
    result = self.fn(*self.args, **self.kwargs)
             ^^^^^^^^^^^^^^^^^^^^^^^^^^^^^^^^^^
  File "/usr/local/python/3.12.1/lib/python3.12/site-packages/scrapli/channel/sync_channel.py", line 297, in channel_authenticate_ssh
    self._ssh_message_handler(output=authenticate_buf)
  File "/usr/local/python/3.12.1/lib/python3.12/site-packages/scrapli/channel/base_channel.py", line 481, in _ssh_message_handler
    raise ScrapliAuthenticationFailed(msg)
scrapli.exceptions.ScrapliAuthenticationFailed: Host key verification failed

2025-09-06 12:42:20,245 - nornir.core.task -    ERROR -      start() - Host 'nxos1': task 'show_version' failed with traceback:
Traceback (most recent call last):
  File "/usr/local/python/3.12.1/lib/python3.12/site-packages/nornir/core/task.py", line 98, in start
    r = self.task(self, **self.params)
        ^^^^^^^^^^^^^^^^^^^^^^^^^^^^^^
  File "/workspaces/Nornir/nornir_nxos/nornir_nxos.py", line 11, in show_version
    result = task.run(
             ^^^^^^^^^
  File "/usr/local/python/3.12.1/lib/python3.12/site-packages/nornir/core/task.py", line 173, in run
    raise NornirSubTaskError(task=run_task, result=r)
nornir.core.exceptions.NornirSubTaskError: Subtask: send_command (failed)


2025-09-06 12:42:23,710 -  nornir.core -     INFO -        run() - Running task 'show_version' with args {} on 1 hosts
2025-09-06 12:42:24,576 - nornir.core.task -    ERROR -      start() - Host 'nxos1': task 'send_command' failed with traceback:
Traceback (most recent call last):
  File "/usr/local/python/3.12.1/lib/python3.12/site-packages/nornir/core/task.py", line 98, in start
    r = self.task(self, **self.params)
        ^^^^^^^^^^^^^^^^^^^^^^^^^^^^^^
  File "/usr/local/python/3.12.1/lib/python3.12/site-packages/nornir_scrapli/tasks/core/send_command.py", line 37, in send_command
    scrapli_conn = task.host.get_connection("scrapli", task.nornir.config)
                   ^^^^^^^^^^^^^^^^^^^^^^^^^^^^^^^^^^^^^^^^^^^^^^^^^^^^^^^
  File "/usr/local/python/3.12.1/lib/python3.12/site-packages/nornir/core/inventory.py", line 476, in get_connection
    self.open_connection(
  File "/usr/local/python/3.12.1/lib/python3.12/site-packages/nornir/core/inventory.py", line 528, in open_connection
    conn_obj.open(
  File "/usr/local/python/3.12.1/lib/python3.12/site-packages/nornir_scrapli/connection.py", line 106, in open
    connection.open()
  File "/usr/local/python/3.12.1/lib/python3.12/site-packages/scrapli/driver/base/sync_driver.py", line 106, in open
    self.channel.channel_authenticate_ssh(
  File "/usr/local/python/3.12.1/lib/python3.12/site-packages/scrapli/decorators.py", line 224, in decorate
    return _multiprocessing_timeout(
           ^^^^^^^^^^^^^^^^^^^^^^^^^
  File "/usr/local/python/3.12.1/lib/python3.12/site-packages/scrapli/decorators.py", line 115, in _multiprocessing_timeout
    return future.result()
           ^^^^^^^^^^^^^^^
  File "/usr/local/python/3.12.1/lib/python3.12/concurrent/futures/_base.py", line 449, in result
    return self.__get_result()
           ^^^^^^^^^^^^^^^^^^^
  File "/usr/local/python/3.12.1/lib/python3.12/concurrent/futures/_base.py", line 401, in __get_result
    raise self._exception
  File "/usr/local/python/3.12.1/lib/python3.12/concurrent/futures/thread.py", line 58, in run
    result = self.fn(*self.args, **self.kwargs)
             ^^^^^^^^^^^^^^^^^^^^^^^^^^^^^^^^^^
  File "/usr/local/python/3.12.1/lib/python3.12/site-packages/scrapli/channel/sync_channel.py", line 297, in channel_authenticate_ssh
    self._ssh_message_handler(output=authenticate_buf)
  File "/usr/local/python/3.12.1/lib/python3.12/site-packages/scrapli/channel/base_channel.py", line 481, in _ssh_message_handler
    raise ScrapliAuthenticationFailed(msg)
scrapli.exceptions.ScrapliAuthenticationFailed: Host key verification failed

2025-09-06 12:42:24,576 - nornir.core.task -    ERROR -      start() - Host 'nxos1': task 'show_version' failed with traceback:
Traceback (most recent call last):
  File "/usr/local/python/3.12.1/lib/python3.12/site-packages/nornir/core/task.py", line 98, in start
    r = self.task(self, **self.params)
        ^^^^^^^^^^^^^^^^^^^^^^^^^^^^^^
  File "/workspaces/Nornir/nornir_nxos/nornir_nxos.py", line 11, in show_version
    result = task.run(
             ^^^^^^^^^
  File "/usr/local/python/3.12.1/lib/python3.12/site-packages/nornir/core/task.py", line 173, in run
    raise NornirSubTaskError(task=run_task, result=r)
nornir.core.exceptions.NornirSubTaskError: Subtask: send_command (failed)


2025-09-06 12:44:24,035 -  nornir.core -     INFO -        run() - Running task 'show_version' with args {} on 1 hosts
2025-09-06 12:44:24,914 - nornir.core.task -    ERROR -      start() - Host 'nxos1': task 'send_command' failed with traceback:
Traceback (most recent call last):
  File "/usr/local/python/3.12.1/lib/python3.12/site-packages/nornir/core/task.py", line 98, in start
    r = self.task(self, **self.params)
        ^^^^^^^^^^^^^^^^^^^^^^^^^^^^^^
  File "/usr/local/python/3.12.1/lib/python3.12/site-packages/nornir_scrapli/tasks/core/send_command.py", line 37, in send_command
    scrapli_conn = task.host.get_connection("scrapli", task.nornir.config)
                   ^^^^^^^^^^^^^^^^^^^^^^^^^^^^^^^^^^^^^^^^^^^^^^^^^^^^^^^
  File "/usr/local/python/3.12.1/lib/python3.12/site-packages/nornir/core/inventory.py", line 476, in get_connection
    self.open_connection(
  File "/usr/local/python/3.12.1/lib/python3.12/site-packages/nornir/core/inventory.py", line 528, in open_connection
    conn_obj.open(
  File "/usr/local/python/3.12.1/lib/python3.12/site-packages/nornir_scrapli/connection.py", line 106, in open
    connection.open()
  File "/usr/local/python/3.12.1/lib/python3.12/site-packages/scrapli/driver/base/sync_driver.py", line 106, in open
    self.channel.channel_authenticate_ssh(
  File "/usr/local/python/3.12.1/lib/python3.12/site-packages/scrapli/decorators.py", line 224, in decorate
    return _multiprocessing_timeout(
           ^^^^^^^^^^^^^^^^^^^^^^^^^
  File "/usr/local/python/3.12.1/lib/python3.12/site-packages/scrapli/decorators.py", line 115, in _multiprocessing_timeout
    return future.result()
           ^^^^^^^^^^^^^^^
  File "/usr/local/python/3.12.1/lib/python3.12/concurrent/futures/_base.py", line 449, in result
    return self.__get_result()
           ^^^^^^^^^^^^^^^^^^^
  File "/usr/local/python/3.12.1/lib/python3.12/concurrent/futures/_base.py", line 401, in __get_result
    raise self._exception
  File "/usr/local/python/3.12.1/lib/python3.12/concurrent/futures/thread.py", line 58, in run
    result = self.fn(*self.args, **self.kwargs)
             ^^^^^^^^^^^^^^^^^^^^^^^^^^^^^^^^^^
  File "/usr/local/python/3.12.1/lib/python3.12/site-packages/scrapli/channel/sync_channel.py", line 297, in channel_authenticate_ssh
    self._ssh_message_handler(output=authenticate_buf)
  File "/usr/local/python/3.12.1/lib/python3.12/site-packages/scrapli/channel/base_channel.py", line 481, in _ssh_message_handler
    raise ScrapliAuthenticationFailed(msg)
scrapli.exceptions.ScrapliAuthenticationFailed: Host key verification failed

2025-09-06 12:44:24,915 - nornir.core.task -    ERROR -      start() - Host 'nxos1': task 'show_version' failed with traceback:
Traceback (most recent call last):
  File "/usr/local/python/3.12.1/lib/python3.12/site-packages/nornir/core/task.py", line 98, in start
    r = self.task(self, **self.params)
        ^^^^^^^^^^^^^^^^^^^^^^^^^^^^^^
  File "/workspaces/Nornir/nornir_nxos/nornir_nxos.py", line 11, in show_version
    result = task.run(
             ^^^^^^^^^
  File "/usr/local/python/3.12.1/lib/python3.12/site-packages/nornir/core/task.py", line 173, in run
    raise NornirSubTaskError(task=run_task, result=r)
nornir.core.exceptions.NornirSubTaskError: Subtask: send_command (failed)


2025-09-06 12:46:04,485 -  nornir.core -     INFO -        run() - Running task 'show_version' with args {} on 1 hosts
2025-09-06 12:46:05,377 - nornir.core.task -    ERROR -      start() - Host 'nxos1': task 'send_command' failed with traceback:
Traceback (most recent call last):
  File "/usr/local/python/3.12.1/lib/python3.12/site-packages/nornir/core/task.py", line 98, in start
    r = self.task(self, **self.params)
        ^^^^^^^^^^^^^^^^^^^^^^^^^^^^^^
  File "/usr/local/python/3.12.1/lib/python3.12/site-packages/nornir_scrapli/tasks/core/send_command.py", line 37, in send_command
    scrapli_conn = task.host.get_connection("scrapli", task.nornir.config)
                   ^^^^^^^^^^^^^^^^^^^^^^^^^^^^^^^^^^^^^^^^^^^^^^^^^^^^^^^
  File "/usr/local/python/3.12.1/lib/python3.12/site-packages/nornir/core/inventory.py", line 476, in get_connection
    self.open_connection(
  File "/usr/local/python/3.12.1/lib/python3.12/site-packages/nornir/core/inventory.py", line 528, in open_connection
    conn_obj.open(
  File "/usr/local/python/3.12.1/lib/python3.12/site-packages/nornir_scrapli/connection.py", line 106, in open
    connection.open()
  File "/usr/local/python/3.12.1/lib/python3.12/site-packages/scrapli/driver/base/sync_driver.py", line 106, in open
    self.channel.channel_authenticate_ssh(
  File "/usr/local/python/3.12.1/lib/python3.12/site-packages/scrapli/decorators.py", line 224, in decorate
    return _multiprocessing_timeout(
           ^^^^^^^^^^^^^^^^^^^^^^^^^
  File "/usr/local/python/3.12.1/lib/python3.12/site-packages/scrapli/decorators.py", line 115, in _multiprocessing_timeout
    return future.result()
           ^^^^^^^^^^^^^^^
  File "/usr/local/python/3.12.1/lib/python3.12/concurrent/futures/_base.py", line 449, in result
    return self.__get_result()
           ^^^^^^^^^^^^^^^^^^^
  File "/usr/local/python/3.12.1/lib/python3.12/concurrent/futures/_base.py", line 401, in __get_result
    raise self._exception
  File "/usr/local/python/3.12.1/lib/python3.12/concurrent/futures/thread.py", line 58, in run
    result = self.fn(*self.args, **self.kwargs)
             ^^^^^^^^^^^^^^^^^^^^^^^^^^^^^^^^^^
  File "/usr/local/python/3.12.1/lib/python3.12/site-packages/scrapli/channel/sync_channel.py", line 297, in channel_authenticate_ssh
    self._ssh_message_handler(output=authenticate_buf)
  File "/usr/local/python/3.12.1/lib/python3.12/site-packages/scrapli/channel/base_channel.py", line 481, in _ssh_message_handler
    raise ScrapliAuthenticationFailed(msg)
scrapli.exceptions.ScrapliAuthenticationFailed: Host key verification failed

2025-09-06 12:46:05,377 - nornir.core.task -    ERROR -      start() - Host 'nxos1': task 'show_version' failed with traceback:
Traceback (most recent call last):
  File "/usr/local/python/3.12.1/lib/python3.12/site-packages/nornir/core/task.py", line 98, in start
    r = self.task(self, **self.params)
        ^^^^^^^^^^^^^^^^^^^^^^^^^^^^^^
  File "/workspaces/Nornir/nornir_nxos/nornir_nxos.py", line 11, in show_version
    result = task.run(
             ^^^^^^^^^
  File "/usr/local/python/3.12.1/lib/python3.12/site-packages/nornir/core/task.py", line 173, in run
    raise NornirSubTaskError(task=run_task, result=r)
nornir.core.exceptions.NornirSubTaskError: Subtask: send_command (failed)


2025-09-06 12:48:40,108 -  nornir.core -     INFO -        run() - Running task 'show_version' with args {} on 1 hosts
2025-09-06 12:48:40,109 - nornir.core.task -    ERROR -      start() - Host 'nxos1': task 'send_command' failed with traceback:
Traceback (most recent call last):
  File "/usr/local/python/3.12.1/lib/python3.12/site-packages/nornir/core/task.py", line 98, in start
    r = self.task(self, **self.params)
        ^^^^^^^^^^^^^^^^^^^^^^^^^^^^^^
TypeError: send_command() got an unexpected keyword argument 'use_strict_key'

2025-09-06 12:48:40,109 - nornir.core.task -    ERROR -      start() - Host 'nxos1': task 'show_version' failed with traceback:
Traceback (most recent call last):
  File "/usr/local/python/3.12.1/lib/python3.12/site-packages/nornir/core/task.py", line 98, in start
    r = self.task(self, **self.params)
        ^^^^^^^^^^^^^^^^^^^^^^^^^^^^^^
  File "/workspaces/Nornir/nornir_nxos/nornir_nxos.py", line 11, in show_version
    result = task.run(
             ^^^^^^^^^
  File "/usr/local/python/3.12.1/lib/python3.12/site-packages/nornir/core/task.py", line 173, in run
    raise NornirSubTaskError(task=run_task, result=r)
nornir.core.exceptions.NornirSubTaskError: Subtask: send_command (failed)


2025-09-06 12:56:38,583 -  nornir.core -     INFO -        run() - Running task 'show_version' with args {} on 1 hosts
2025-09-06 12:56:39,665 - nornir.core.task -    ERROR -      start() - Host 'nxos1': task 'send_command' failed with traceback:
Traceback (most recent call last):
  File "/usr/local/python/3.12.1/lib/python3.12/site-packages/nornir/core/task.py", line 98, in start
    r = self.task(self, **self.params)
        ^^^^^^^^^^^^^^^^^^^^^^^^^^^^^^
  File "/usr/local/python/3.12.1/lib/python3.12/site-packages/nornir_scrapli/tasks/core/send_command.py", line 37, in send_command
    scrapli_conn = task.host.get_connection("scrapli", task.nornir.config)
                   ^^^^^^^^^^^^^^^^^^^^^^^^^^^^^^^^^^^^^^^^^^^^^^^^^^^^^^^
  File "/usr/local/python/3.12.1/lib/python3.12/site-packages/nornir/core/inventory.py", line 476, in get_connection
    self.open_connection(
  File "/usr/local/python/3.12.1/lib/python3.12/site-packages/nornir/core/inventory.py", line 528, in open_connection
    conn_obj.open(
  File "/usr/local/python/3.12.1/lib/python3.12/site-packages/nornir_scrapli/connection.py", line 106, in open
    connection.open()
  File "/usr/local/python/3.12.1/lib/python3.12/site-packages/scrapli/driver/base/sync_driver.py", line 106, in open
    self.channel.channel_authenticate_ssh(
  File "/usr/local/python/3.12.1/lib/python3.12/site-packages/scrapli/decorators.py", line 224, in decorate
    return _multiprocessing_timeout(
           ^^^^^^^^^^^^^^^^^^^^^^^^^
  File "/usr/local/python/3.12.1/lib/python3.12/site-packages/scrapli/decorators.py", line 115, in _multiprocessing_timeout
    return future.result()
           ^^^^^^^^^^^^^^^
  File "/usr/local/python/3.12.1/lib/python3.12/concurrent/futures/_base.py", line 449, in result
    return self.__get_result()
           ^^^^^^^^^^^^^^^^^^^
  File "/usr/local/python/3.12.1/lib/python3.12/concurrent/futures/_base.py", line 401, in __get_result
    raise self._exception
  File "/usr/local/python/3.12.1/lib/python3.12/concurrent/futures/thread.py", line 58, in run
    result = self.fn(*self.args, **self.kwargs)
             ^^^^^^^^^^^^^^^^^^^^^^^^^^^^^^^^^^
  File "/usr/local/python/3.12.1/lib/python3.12/site-packages/scrapli/channel/sync_channel.py", line 297, in channel_authenticate_ssh
    self._ssh_message_handler(output=authenticate_buf)
  File "/usr/local/python/3.12.1/lib/python3.12/site-packages/scrapli/channel/base_channel.py", line 481, in _ssh_message_handler
    raise ScrapliAuthenticationFailed(msg)
scrapli.exceptions.ScrapliAuthenticationFailed: Host key verification failed

2025-09-06 12:56:39,666 - nornir.core.task -    ERROR -      start() - Host 'nxos1': task 'show_version' failed with traceback:
Traceback (most recent call last):
  File "/usr/local/python/3.12.1/lib/python3.12/site-packages/nornir/core/task.py", line 98, in start
    r = self.task(self, **self.params)
        ^^^^^^^^^^^^^^^^^^^^^^^^^^^^^^
  File "/workspaces/Nornir/nornir_nxos/nornir_nxos.py", line 5, in show_version
    result = task.run(task=send_command, command="show version")
             ^^^^^^^^^^^^^^^^^^^^^^^^^^^^^^^^^^^^^^^^^^^^^^^^^^^
  File "/usr/local/python/3.12.1/lib/python3.12/site-packages/nornir/core/task.py", line 173, in run
    raise NornirSubTaskError(task=run_task, result=r)
nornir.core.exceptions.NornirSubTaskError: Subtask: send_command (failed)


2025-09-06 12:57:58,417 -  nornir.core -     INFO -        run() - Running task 'send_command' with args {'command': 'show version'} on 1 hosts
2025-09-06 12:57:59,298 - nornir.core.task -    ERROR -      start() - Host 'nxos1': task 'send_command' failed with traceback:
Traceback (most recent call last):
  File "/usr/local/python/3.12.1/lib/python3.12/site-packages/nornir/core/task.py", line 98, in start
    r = self.task(self, **self.params)
        ^^^^^^^^^^^^^^^^^^^^^^^^^^^^^^
  File "/usr/local/python/3.12.1/lib/python3.12/site-packages/nornir_scrapli/tasks/core/send_command.py", line 37, in send_command
    scrapli_conn = task.host.get_connection("scrapli", task.nornir.config)
                   ^^^^^^^^^^^^^^^^^^^^^^^^^^^^^^^^^^^^^^^^^^^^^^^^^^^^^^^
  File "/usr/local/python/3.12.1/lib/python3.12/site-packages/nornir/core/inventory.py", line 476, in get_connection
    self.open_connection(
  File "/usr/local/python/3.12.1/lib/python3.12/site-packages/nornir/core/inventory.py", line 528, in open_connection
    conn_obj.open(
  File "/usr/local/python/3.12.1/lib/python3.12/site-packages/nornir_scrapli/connection.py", line 106, in open
    connection.open()
  File "/usr/local/python/3.12.1/lib/python3.12/site-packages/scrapli/driver/base/sync_driver.py", line 106, in open
    self.channel.channel_authenticate_ssh(
  File "/usr/local/python/3.12.1/lib/python3.12/site-packages/scrapli/decorators.py", line 224, in decorate
    return _multiprocessing_timeout(
           ^^^^^^^^^^^^^^^^^^^^^^^^^
  File "/usr/local/python/3.12.1/lib/python3.12/site-packages/scrapli/decorators.py", line 115, in _multiprocessing_timeout
    return future.result()
           ^^^^^^^^^^^^^^^
  File "/usr/local/python/3.12.1/lib/python3.12/concurrent/futures/_base.py", line 449, in result
    return self.__get_result()
           ^^^^^^^^^^^^^^^^^^^
  File "/usr/local/python/3.12.1/lib/python3.12/concurrent/futures/_base.py", line 401, in __get_result
    raise self._exception
  File "/usr/local/python/3.12.1/lib/python3.12/concurrent/futures/thread.py", line 58, in run
    result = self.fn(*self.args, **self.kwargs)
             ^^^^^^^^^^^^^^^^^^^^^^^^^^^^^^^^^^
  File "/usr/local/python/3.12.1/lib/python3.12/site-packages/scrapli/channel/sync_channel.py", line 297, in channel_authenticate_ssh
    self._ssh_message_handler(output=authenticate_buf)
  File "/usr/local/python/3.12.1/lib/python3.12/site-packages/scrapli/channel/base_channel.py", line 481, in _ssh_message_handler
    raise ScrapliAuthenticationFailed(msg)
scrapli.exceptions.ScrapliAuthenticationFailed: Host key verification failed

2025-09-06 13:00:10,918 -  nornir.core -     INFO -        run() - Running task 'netmiko_send_command' with args {'command_string': 'show version'} on 1 hosts
2025-09-06 13:01:32,465 -  nornir.core -     INFO -        run() - Running task 'netmiko_send_command' with args {'command_string': 'show version'} on 1 hosts
2025-09-06 13:01:55,401 -  nornir.core -     INFO -        run() - Running task 'netmiko_send_command' with args {'command_string': 'show version'} on 1 hosts
2025-09-06 13:08:42,545 -  nornir.core -     INFO -        run() - Running task 'check_config' with args {'feature': 'nxos'} on 1 hosts
2025-09-06 13:08:44,546 - nornir.core.task -    ERROR -      start() - Host 'nxos1': task 'check_config' failed with traceback:
Traceback (most recent call last):
  File "/usr/local/python/3.12.1/lib/python3.12/site-packages/nornir/core/task.py", line 98, in start
    r = self.task(self, **self.params)
        ^^^^^^^^^^^^^^^^^^^^^^^^^^^^^^
  File "/workspaces/Nornir/nornir_nxos/check_feature.py", line 12, in check_config
    message = f"{task.host.name} {feature} is {task.host[data_key]}"
                                               ~~~~~~~~~^^^^^^^^^^
  File "/usr/local/python/3.12.1/lib/python3.12/site-packages/nornir/core/inventory.py", line 337, in __getitem__
    return self.data[item]
           ~~~~~~~~~^^^^^^
KeyError: 'nxos_server'

2025-09-06 13:09:52,437 -  nornir.core -     INFO -        run() - Running task 'check_config' with args {'feature': 'nxos'} on 1 hosts
2025-09-06 13:09:54,439 - nornir.core.task -    ERROR -      start() - Host 'nxos1': task 'check_config' failed with traceback:
Traceback (most recent call last):
  File "/usr/local/python/3.12.1/lib/python3.12/site-packages/nornir/core/task.py", line 98, in start
    r = self.task(self, **self.params)
        ^^^^^^^^^^^^^^^^^^^^^^^^^^^^^^
  File "/workspaces/Nornir/nornir_nxos/check_feature.py", line 12, in check_config
    message = f"{task.host.name} {feature} is {task.host[data_key]}"
                                               ~~~~~~~~~^^^^^^^^^^
  File "/usr/local/python/3.12.1/lib/python3.12/site-packages/nornir/core/inventory.py", line 337, in __getitem__
    return self.data[item]
           ~~~~~~~~~^^^^^^
KeyError: 'nxos_server'

2025-09-06 13:09:59,376 -  nornir.core -     INFO -        run() - Running task 'check_config' with args {'feature': 'nxos'} on 1 hosts
2025-09-06 13:10:01,378 - nornir.core.task -    ERROR -      start() - Host 'nxos1': task 'check_config' failed with traceback:
Traceback (most recent call last):
  File "/usr/local/python/3.12.1/lib/python3.12/site-packages/nornir/core/task.py", line 98, in start
    r = self.task(self, **self.params)
        ^^^^^^^^^^^^^^^^^^^^^^^^^^^^^^
  File "/workspaces/Nornir/nornir_nxos/check_feature.py", line 12, in check_config
    message = f"{task.host.name} {feature} is {task.host[data_key]}"
                                               ~~~~~~~~~^^^^^^^^^^
  File "/usr/local/python/3.12.1/lib/python3.12/site-packages/nornir/core/inventory.py", line 337, in __getitem__
    return self.data[item]
           ~~~~~~~~~^^^^^^
KeyError: 'nxos_server'

2025-09-06 13:13:45,224 -  nornir.core -     INFO -        run() - Running task 'check_config' with args {'feature': 'nxos'} on 1 hosts
2025-09-06 13:15:49,879 -  nornir.core -     INFO -        run() - Running task 'check_config' with args {'feature': 'nxos'} on 1 hosts
2025-09-07 22:23:38,206 -  nornir.core -     INFO -        run() - Running task 'show_version' with args {} on 1 hosts
2025-09-07 22:23:53,410 - nornir.core.task -    ERROR -      start() - Host 'nxos1': task 'send_command' failed with traceback:
Traceback (most recent call last):
  File "/usr/local/python/3.12.1/lib/python3.12/site-packages/nornir/core/task.py", line 98, in start
    r = self.task(self, **self.params)
        ^^^^^^^^^^^^^^^^^^^^^^^^^^^^^^
  File "/usr/local/python/3.12.1/lib/python3.12/site-packages/nornir_scrapli/tasks/core/send_command.py", line 37, in send_command
    scrapli_conn = task.host.get_connection("scrapli", task.nornir.config)
                   ^^^^^^^^^^^^^^^^^^^^^^^^^^^^^^^^^^^^^^^^^^^^^^^^^^^^^^^
  File "/usr/local/python/3.12.1/lib/python3.12/site-packages/nornir/core/inventory.py", line 476, in get_connection
    self.open_connection(
  File "/usr/local/python/3.12.1/lib/python3.12/site-packages/nornir/core/inventory.py", line 528, in open_connection
    conn_obj.open(
  File "/usr/local/python/3.12.1/lib/python3.12/site-packages/nornir_scrapli/connection.py", line 106, in open
    connection.open()
  File "/usr/local/python/3.12.1/lib/python3.12/site-packages/scrapli/driver/base/sync_driver.py", line 106, in open
    self.channel.channel_authenticate_ssh(
  File "/usr/local/python/3.12.1/lib/python3.12/site-packages/scrapli/decorators.py", line 224, in decorate
    return _multiprocessing_timeout(
           ^^^^^^^^^^^^^^^^^^^^^^^^^
  File "/usr/local/python/3.12.1/lib/python3.12/site-packages/scrapli/decorators.py", line 115, in _multiprocessing_timeout
    return future.result()
           ^^^^^^^^^^^^^^^
  File "/usr/local/python/3.12.1/lib/python3.12/concurrent/futures/_base.py", line 449, in result
    return self.__get_result()
           ^^^^^^^^^^^^^^^^^^^
  File "/usr/local/python/3.12.1/lib/python3.12/concurrent/futures/_base.py", line 401, in __get_result
    raise self._exception
  File "/usr/local/python/3.12.1/lib/python3.12/concurrent/futures/thread.py", line 58, in run
    result = self.fn(*self.args, **self.kwargs)
             ^^^^^^^^^^^^^^^^^^^^^^^^^^^^^^^^^^
  File "/usr/local/python/3.12.1/lib/python3.12/site-packages/scrapli/channel/sync_channel.py", line 297, in channel_authenticate_ssh
    self._ssh_message_handler(output=authenticate_buf)
  File "/usr/local/python/3.12.1/lib/python3.12/site-packages/scrapli/channel/base_channel.py", line 481, in _ssh_message_handler
    raise ScrapliAuthenticationFailed(msg)
scrapli.exceptions.ScrapliAuthenticationFailed: Timed out connecting to host

2025-09-07 22:23:53,410 - nornir.core.task -    ERROR -      start() - Host 'nxos1': task 'show_version' failed with traceback:
Traceback (most recent call last):
  File "/usr/local/python/3.12.1/lib/python3.12/site-packages/nornir/core/task.py", line 98, in start
    r = self.task(self, **self.params)
        ^^^^^^^^^^^^^^^^^^^^^^^^^^^^^^
  File "/workspaces/Nornir/nornir_nxos/simple_scrapli.py", line 9, in show_version
    result = task.run(task=send_command, command="show version")
             ^^^^^^^^^^^^^^^^^^^^^^^^^^^^^^^^^^^^^^^^^^^^^^^^^^^
  File "/usr/local/python/3.12.1/lib/python3.12/site-packages/nornir/core/task.py", line 173, in run
    raise NornirSubTaskError(task=run_task, result=r)
nornir.core.exceptions.NornirSubTaskError: Subtask: send_command (failed)


